[0m17:12:51.840040 [debug] [MainThread]: Sending event: {'category': 'dbt', 'action': 'invocation', 'label': 'start', 'context': [<snowplow_tracker.self_describing_json.SelfDescribingJson object at 0x0000016260D90290>, <snowplow_tracker.self_describing_json.SelfDescribingJson object at 0x00000162641323F0>, <snowplow_tracker.self_describing_json.SelfDescribingJson object at 0x0000016264133FB0>]}


============================== 17:12:51.850679 | eb89fe38-5aed-4d9f-add0-6e4001c50569 ==============================
[0m17:12:51.850679 [info ] [MainThread]: Running with dbt=1.10.4
[0m17:12:51.851769 [debug] [MainThread]: running dbt with arguments {'printer_width': '80', 'indirect_selection': 'eager', 'log_cache_events': 'False', 'write_json': 'True', 'partial_parse': 'True', 'cache_selected_only': 'False', 'profiles_dir': 'C:\\Users\\spide\\.dbt', 'version_check': 'True', 'fail_fast': 'False', 'log_path': 'logs', 'warn_error': 'None', 'debug': 'False', 'use_colors': 'True', 'use_experimental_parser': 'False', 'no_print': 'None', 'quiet': 'False', 'empty': 'False', 'warn_error_options': 'WarnErrorOptionsV2(error=[], warn=[], silence=[])', 'invocation_command': 'dbt run --full-refresh', 'static_parser': 'True', 'log_format': 'default', 'target_path': 'None', 'introspect': 'True', 'send_anonymous_usage_stats': 'True'}
[0m17:12:51.852853 [error] [MainThread]: Encountered an error:
Runtime Error
  No dbt_project.yml found at expected path C:\Users\spide\Downloads\Foundry AI\M03W01\dbt-dag\dbt_project.yml
  Verify that each entry within packages.yml (and their transitive dependencies) contains a file named dbt_project.yml
  
[0m17:12:51.855263 [debug] [MainThread]: Command `dbt run` failed at 17:12:51.854614 after 0.28 seconds
[0m17:12:51.855846 [debug] [MainThread]: Sending event: {'category': 'dbt', 'action': 'invocation', 'label': 'end', 'context': [<snowplow_tracker.self_describing_json.SelfDescribingJson object at 0x0000016260D90290>, <snowplow_tracker.self_describing_json.SelfDescribingJson object at 0x0000016264E22480>, <snowplow_tracker.self_describing_json.SelfDescribingJson object at 0x0000016264E225A0>]}
[0m17:12:51.856472 [debug] [MainThread]: Flushing usage events
[0m17:12:53.462181 [debug] [MainThread]: An error was encountered while trying to flush usage events
